Workbook
Name Acrobatics: #REF!
Name AcrobaticsMerit: 'General Merits'!$A$115
Name AcrobaticsTitle: #REF!
Name Aegis: #REF!
Name Age: #REF!
Name AGI: #REF!
Name AGIMerit: 'General Merits'!$A$17
Name AGITitle: #REF!
Name Alchemy: #REF!
Name AlchemyBase: #REF!
Name AlchemyMerit: 'General Merits'!$A$162
Name AlchemyTitle: #REF!
Name AncientDraconic: #REF!
Name AncientDraconicTitle: #REF!
Name AnimalHandling: #REF!
Name AnimalHandlingBase: #REF!
Name AnimalHandlingMerit: 'General Merits'!$A$166
Name AnimalHandlingTitle: #REF!
Name Appraisal: #REF!
Name AppraisalBase: #REF!
Name AppraisalMerit: 'General Merits'!$A$119
Name AppraisalTitle: #REF!
Name AquaElven: #REF!
Name AquaElvenTitle: #REF!
Name Arcana: #REF!
Name ArcanaBase: #REF!
Name ArcanaMerit: 'General Merits'!$A$170
Name ArcanaTitle: #REF!
Name Archery: #REF!
Name ArcheryBase: #REF!
Name ArcheryMerit: 'General Merits'!$A$52
Name ArcheryTitle: #REF!
Name Armor: #REF!
Name ArmorValue: #REF!
Name Arms: 'Pro Inventory'!$AK$26
Name Athletics: #REF!
Name AthleticsMerit: 'General Merits'!$A$123
Name AthleticsTitle: #REF!
Name AttackPower: #REF!
Name AttackPower: #REF!
Name Axes: #REF!
Name AxesBase: #REF!
Name AxesMerit: 'General Merits'!$A$56
Name AxesTitle: #REF!
Name Back: 'Pro Inventory'!$C$3
Name BaseAGI: #REF!
Name BaseCHA: #REF!
Name BaseCNV: #REF!
Name BaseCON: #REF!
Name BaseFOC: #REF!
Name BaseHeight: #REF!
Name BaseINS: #REF!
Name BaseINT: #REF!
Name BaseSTR: #REF!
Name BaseWeight: #REF!
Name BaseWIS: #REF!
Name BaseWIT: #REF!
Name BasicElven: #REF!
Name BasicElvenMerit: 'General Merits'!$A$217
Name BasicElvenTitle: #REF!

Sheet #Skill Templates
L2: _________ Skills | AN2: Bonus Exp | BI2: Free Range EXP | BT2: =VLOOKUP(#REF!,[2]Descriptions!$A:$U,COLUMN([2]Descriptions!$D:$D),0) -> #REF!
A3: Helper Cells. These columns should be hidden
AN4: =MAX(0,EXP.Combat-EXPSpent.Combat) -> #NAME? | AS4: of | AV4: =EXP.Combat -> #NAME? | BK4: =EXP.Available -> #REF!
B8: =SUM(D:D) -> 0 | F8: =SUM(G:G) -> 0
D10: Sums --> | G10: Sums -->
B17: =B3+1 -> 1 | I17: =I3+D6 -> 0
B19: Cost of first rank –>
D20: =SUM(21:21) -> 0
F21: Sums Row -->
G24: =SUM(26:26) -> 0
I26: Sums Row -->
A27: 4 Cell Gap | E27: 4 Cell Gap | I27: 4 Cell Gap
B31: =B17+1 -> 2 | I31: =I17+D20 -> 0 | P31: Skill Name | AX31: Skill Name | CB31: Skill Name | DH31: Skill Name
BN32: =HYPERLINK("http://wiki.project-saros.com/w/"&AX31,"View Online") -> View Online | CR32: =HYPERLINK("http://wiki.project-saros.com/w/"&CB31,"View Online") -> View Online | DX32: =HYPERLINK("http://wiki.project-saros.com/w/"&DH31,"View Online") -> View Online
B33: Cost of first rank –> | N33: 1 | AA33: =HYPERLINK("http://wiki.project-saros.com/w/"&P31,"View Online") -> View Online | BZ33: 0 | DF33: 0
D34: =SUM(35:35) -> 0 | Q34: Next Point: | W34: =IF(AC40<0,"✗",IF(AC40>0,"✓",SUM(P36+$B31&" xp"))) -> ✗ | AY34: Next Point: | BE34: =IF(BL40<0,"✗",IF(BL40>0,"✓",SUM(AX36:BQ37)+$B31&" xp")) -> ✗ | CC34: Next Point: | CI34: =IF(CP40<0,"✗",IF(CP40>0,"✓",SUM(CB36:CU37)+$B31&" xp")) -> ✗ | DI34: Next Point: | DO34: =IF(DV40<0,"✗",IF(DV40>0,"✓",SUM(DH36:EA37)+$B31&" xp")) -> ✗
F35: Sums Row --> | N35: =IF(AC40<0,0,SUM(P36)) -> 0 | AV35: =IF(BL40<0,0,SUM(AX36:BQ37)) -> 0 | BZ35: =IF(CP40<0,0,SUM(CB36:CU37)) -> 0 | DF35: =IF(DV40<0,0,SUM(DH36:EE37)) -> 0
P36: 0 | AX36: 5 | CB36: 0 | CN36: =IF(AND(CB36=3,CN38<>5),1,0) -> 0 | CR36: =IF(AND(CN36<>0,CR38<>5),1,0) -> 0 | DH36: 0 | DT36: =IF(AND(DH36=3,DT38<>5),1,0) -> 0 | DX36: =IF(AND(DT36<>0,DX38<>5),1,0) -> 0 | EB36: =IF(AND(DX36<>0,EB38<>5),1,0) -> 0
G38: =SUM(40:40) -> 0 | N38: =IF(($B31-1)*6<=$I31,"","Need "&($B31-1)*6-$I31& " more rank(s) in "&$L$2&". ")&IF(OR(N33<>1,OFFSET(U17,4,-2)>=3),"","Need "&3-OFFSET(U17,4,-2)&" more rank(s) in "&U17&".") -> Need 6 more rank(s) in _________ Skills. Need 3 more rank(s) in . | AV38: =IF(($B31-1)*6<=$I31,"","Need "&($B31-1)*6-$I31& " more rank(s) in "&$L$2&". ")&IF(OR(AV33<>1,OFFSET(BC17,4,-2)>=3),"","Need "&3-OFFSET(BC17,4,-2)&" more rank(s) in "&BC17&".") -> Need 6 more rank(s) in _________ Skills. | BZ38: =IF(($B31-1)*6<=$I31,"","Need "&($B31-1)*6-$I31& " more rank(s) in "&$L$2&". ")&IF(OR(BZ33<>1,OFFSET(CG17,4,-2)>=3),"","Need "&3-OFFSET(CG17,4,-2)&" more rank(s) in "&CG17&".") -> Need 6 more rank(s) in _________ Skills. | CN38: 5 | CR38: 5 | DF38: =IF(($B31-1)*6<=$I31,"","Need "&($B31-1)*6-$I31& " more rank(s) in "&$L$2&". ")&IF(OR(DF33<>1,OFFSET(DM17,4,-2)>=3),"","Need "&3-OFFSET(DM17,4,-2)&" more rank(s) in "&DM17&".") -> Need 6 more rank(s) in _________ Skills. | DT38: 5 | DX38: 5 | EB38: 5
I40: Sums Row --> | AB40: =IF(AC40<0,0,((P36+$B31-1)*(P36+$B31)/2)-($B31*($B31-1)/2)) -> 0 | AC40: =IF(N38<>"",-1,IF(P36=1,1,0)) -> -1 | AD40: =-AE40-AC40 -> 1 | AE40: =P36+AB38*0.1+AF38*0.01+AJ38*0.001 -> 0 | BJ40: =IF(BL40<0,0,((SUM(AX36,BJ36,BN36,BR36)+$B31-1)*(SUM(AX36,BJ36,BN36,BR36)+$B31)/2)-($B31*($B31-1)/2)) -> 0 | BL40: =IF(AV38<>"",-1,IF(AX36=5,1,0)) -> -1 | BN40: =-BP40-BL40 -> -4 | BP40: =AX36+BJ38*0.1+BN38*0.01+BR38*0.001 -> 5 | CN40: =IF(CP40<0,0,((SUM(CB36,CN36,CR36,CV36)+$B31-1)*(SUM(CB36,CN36,CR36,CV36)+$B31)/2)-($B31*($B31-1)/2)) -> 0 | CP40: =IF(BZ38<>"",-1,IF(CR36=1,1,0)) -> -1 | CR40: =-CT40-CP40 -> 0.45 | CT40: =CB36+CN38*0.1+CR38*0.01+CV38*0.001 -> 0.55 | DT40: =IF(DV40<0,0,((SUM(DH36,DT36,DX36,EB36)+$B31-1)*(SUM(DH36,DT36,DX36,EB36)+$B31)/2)-($B31*($B31-1)/2)) -> 0 | DV40: =IF(DF38<>"",-1,IF(EB36=1,1,0)) -> -1 | DX40: =-DZ40-DV40 -> 0.445 | DZ40: =DH36+DT38*0.1+DX38*0.01+EB38*0.001 -> 0.555
A41: 4 Cell Gap | E41: 4 Cell Gap | I41: 4 Cell Gap
B45: =B31+1 -> 3 | I45: =I31+D34 -> 0
B47: Cost of first rank –>
D48: =SUM(49:49) -> 0
F49: Sums Row -->
G52: =SUM(54:54) -> 0
I54: Sums Row --> | EL54: =FLOOR((EG54/5),1) -> 0
A55: 4 Cell Gap | E55: 4 Cell Gap | I55: 4 Cell Gap
B59: =B45+1 -> 4 | I59: =I45+D48 -> 0
B61: Cost of first rank –>
D62: =SUM(63:63) -> 0
F63: Sums Row -->
FP64: =FLOOR((FK64/5),1) -> 0
G66: =SUM(68:68) -> 0
I68: Sums Row -->
A69: 4 Cell Gap | E69: 4 Cell Gap | I69: 4 Cell Gap
B73: =B59+1 -> 5 | I73: =I59+D62 -> 0
B75: Cost of first rank –>
D76: =SUM(77:77) -> 0
F77: Sums Row -->
...

Sheet Descriptions
A1: Races | C1: Plural | D1: Description
A2: Dwarf | C2: Dwarves | D2: Born of the of earth and fire, dwarves are strong, stout individuals carving mighty stone fortresses in the mountainsides. Dwarves are expert miners, smiths, and unyielding front line soldiers.
A3: Garona | C3: Garona
A4: Gnome | C4: Gnomes | D4: Believed to be cousins of the Dwarves, gnomes are principally known for being inquisitive and mechanically-inclined, the innovative gnomish people explore and unearth history and previously undiscovered lands. While not physically adept, gnomes are pioneers of ingeniuty and tactics specializing in infiltration, arcane magics, and technology.
A5: Half-Elf | C5: Half-elves
A6: Human | C6: Humans | D6: Of all the civilized races, humans are the most adaptable and diverse. Human settlements can be found almost anywhere, and human morals, customs, and interests vary greatly.
A7: Kender | C7: Kender | D7: The small, playful race of elves are commonly mistaken for the children of elves. Kender have a mischievious history, seeking excitement and danger at every opportunity. Many more refined races believe that kender fear nothing at all and see only joy and wonder in the world.
A8: Krothgar | C8: Krothgar | D8: Though the Krothgar have an ancestry of war, they turned off away from the path of pointless battle and meaningless conflict. Descending from orcs, the Krothgar are no longer the mindless servants of Il'Grek, the goblin god of war. Instead they have turned to the deities of the dwarves and, over time, earned a place under the gods' banner. Though the dwarves are still rather unforgiving of their heritage, the Krothgar lead peaceful lives among the elves, and humans of the world.
A9: Shadow Elf | C9: Shadow elves | D9: Shadow elves are intelligent, cunning, and devious. Having a different perspective on the world than others they see the humor in the darkness, the purposefulness of death, and show an understanding and appreciation for the unknown. They find it difficult to trust others that have not proven themselves, but are capable of quickly spotting potential loyalty and friends when necessary. Their obsession for the truth drives them to constantly question the motives of others and what secrets they are hiding.
A10: Volkmyr | C10: Volkmyr | D10: Commonly confused for lycanthropes, the strong, noble, race of volkmyr are a fey race that have evolved directly from the wolves. With small packs spread through much of uncivilized territories, the primary home of the volkmyr is in the cold north
A11: Wind Elf | C11: Wind Elves | D11: Creatures of magic with strong ties to to the sun and moon, wind elves live in vast, luxurious cities across most of the known world.
A12: Wood Elf | C12: Wood elves | D12: Wood elf description
A13: Manakin | C13: Manakins | D13: Magical constructs
A14: Ersatz | C14: Ersatz | D14: Ersatz construction
A15: Lagamo | C15: Lagami | D15: Lagamo descrakda | Q15: 15
A16: Mau | C16: Mau | D16: WSORDS
A17: Sylvan | C17: Sylvans | D17: more words | M17: SKILL | N17: SPENT
A18: Bonuses | M18: 1 | N18: 1
A19: Penalties | M19: 2 | N19: =N18+IF(M18/5<$Q$15/5,1,FLOOR(M18/5,1)-1) -> 2
A20: STR | M20: 3 | N20: =N19+IF(M19/5<$Q$15/5,1,FLOOR(M19/5,1)-1) -> 3
A21: AGI | M21: 4 | N21: =N20+IF(M20/5<$Q$15/5,1,FLOOR(M20/5,1)-1) -> 4
A22: CON | M22: 5 | N22: =N21+IF(M21/5<$Q$15/5,1,FLOOR(M21/5,1)-1) -> 5
A23: INT | M23: 6 | N23: =N22+IF(M22/5<$Q$15/5,1,FLOOR(M22/5,1)-1) -> 6
A24: WIS | M24: 7 | N24: =N23+IF(M23/5<$Q$15/5,1,FLOOR(M23/5,1)-1) -> 7
A25: FOC | M25: 8 | N25: =N24+IF(M24/5<$Q$15/5,1,FLOOR(M24/5,1)-1) -> 8
A26: CHA | M26: 9 | N26: =N25+IF(M25/5<$Q$15/5,1,FLOOR(M25/5,1)-1) -> 9
A27: INS | M27: 10 | N27: =N26+IF(M26/5<$Q$15/5,1,FLOOR(M26/5,1)-1) -> 10
A28: CNV | M28: 11 | N28: =N27+IF(M27/5<$Q$15/5,1,FLOOR(M27/5,1)-1) -> 11
A29: Defense Bonus | M29: 12 | N29: =N28+IF(M28/5<$Q$15/5,1,FLOOR(M28/5,1)-1) -> 12
A30: Reflex | M30: 13 | N30: =N29+IF(M29/5<$Q$15/5,1,FLOOR(M29/5,1)-1) -> 13
... A51: Davek | M51: 34 | N51: =N50+IF(M50/5<$Q$15/5,1,FLOOR(M50/5,1)-1) -> 80
A52: Geovek
A53: Goblin
A54: Gnomish
A55: Volken
A56: Skill Bonus
A57: Earthen Ingenuity | D57: The complexity for checks that involve working with stone or metal is reduced by 1.
A58: =FALSE() -> FALSE | D58: The complexity for checks that involve FALSE is reduced by 1.
A59: Olfactory Savant | D59: The complexity for checks that involve working with stone or metal is reduced by 1.
A60: =FALSE() -> FALSE | D60: The complexity for checks that involve FALSE is reduced by 1.
...

Sheet General Merits
B1: EXPERIENCE POINTS
B3: Starting | K3: Earned | T3: Spent | AC3: Remaining | AL3: =IF(Race="Human","Human: +10% exp bonus included.","") -> #REF!
B5: 1000 | K5: 0 | T5: =SUM(K:M) -> #REF! | AC5: =SUM(B5,K5,'OLD Pro Sheet'!A70:I71)*IF(Race="Human",1.1,1)-T5 -> #REF!
A8: Chosen | G8: Merit Name | Z8: Cost (Exp) | AH8: Requires | AX8: Description | DS8: Strength | DT8: Agility | DU8: Constitution | DV8: Intelligence | DW8: Wisdom | DX8: Focus | DY8: Charism | DZ8: Insight | EA8: Conviction | EB8: Archery | EC8: Crossbows | ED8: Daggers | EE8: H2H | EF8: Heavy Armor | EG8: Improvised | EH8: Light Armor | EI8: Light Armor | EJ8: Light Armor | EK8: Light Armor | EL8: Light Armor | EM8: Light Armor | EN8: Light Armor | EO8: Light Armor | EP8: Light Armor | EQ8: Light Armor
B10: Ability Score Increase
A13: 0 | G13: Strength | Z13: =STR*5 -> #REF! | AX13: ="Further increases your Strength score from "&STR&" to "&STR+1 -> #REF!
F16: =G13 -> Strength | K16: =(STR*(STR-1)/2-(BaseSTR*(BaseSTR-1))/2)*5 -> #REF! | N16: =IF(AH9<>"",VLOOKUP($G13,'Merit Data'!A:BW,MATCH('Merit Data'!$B$3,'Merit Data'!$3:$3,0),0),TRUE) -> TRUE | X16: =IF(F16>0,HYPERLINK("http://wiki.project-saros.com/w/"&F16,"Info"),"") -> Info
A17: 0 | G17: Agility | Z17: =AGI*5 -> #REF! | AX17: ="Further increases your Agility score from "&AGI&" to "&AGI+1 -> #REF!
F20: =G17 -> Agility | K20: =(AGI*(AGI-1)/2-(BaseAGI*(BaseAGI-1))/2)*5 -> #REF! | N20: =IF(AH13<>"",VLOOKUP($G17,'Merit Data'!A:BW,MATCH('Merit Data'!$B$3,'Merit Data'!$3:$3,0),0),TRUE) -> TRUE | X20: =IF(F20>0,HYPERLINK("http://wiki.project-saros.com/w/"&F20,"Info"),"") -> Info
A21: 0 | G21: Constitution | Z21: =CON*5 -> #REF! | AX21: ="Further increases your Constitution score from "&CON&" to "&CON+1 -> #REF!
F24: =G21 -> Constitution | K24: =(CON*(CON-1)/2-(BaseCON*(BaseCON-1))/2)*5 -> #REF! | N24: =IF(AH17<>"",VLOOKUP($G21,'Merit Data'!A:BW,MATCH('Merit Data'!$B$3,'Merit Data'!$3:$3,0),0),TRUE) -> TRUE | X24: =IF(F24>0,HYPERLINK("http://wiki.project-saros.com/w/"&F24,"Info"),"") -> Info
A25: 0 | G25: Intelligence | Z25: =INT*5 -> #REF! | AX25: ="Further increases your Intelligence score from "&INT&" to "&INT+1 -> #REF!
F28: =G25 -> Intelligence | K28: =(INT*(INT-1)/2-(BaseINT*(BaseINT-1))/2)*5 -> #REF! | N28: =IF(AH21<>"",VLOOKUP($G25,'Merit Data'!A:BW,MATCH('Merit Data'!$B$3,'Merit Data'!$3:$3,0),0),TRUE) -> TRUE | X28: =IF(F28>0,HYPERLINK("http://wiki.project-saros.com/w/"&F28,"Info"),"") -> Info
A29: 0 | G29: Wisdom | Z29: =WIS*5 -> #REF! | AX29: ="Further increases your Wisdom score from "&WIS&" to "&WIS+1 -> #REF!
F32: =G29 -> Wisdom | K32: =(WIS*(WIS-1)/2-(BaseWIS*(BaseWIS-1))/2)*5 -> #REF! | N32: =IF(AH25<>"",VLOOKUP($G29,'Merit Data'!A:BW,MATCH('Merit Data'!$B$3,'Merit Data'!$3:$3,0),0),TRUE) -> TRUE | X32: =IF(F32>0,HYPERLINK("http://wiki.project-saros.com/w/"&F32,"Info"),"") -> Info
A33: 0 | G33: Focus | Z33: =FOC*5 -> #REF! | AX33: ="Further increases your Focus score from "&FOC&" to "&FOC+1 -> #REF!
F36: =G33 -> Focus | K36: =(FOC*(FOC-1)/2-(BaseFOC*(BaseFOC-1))/2)*5 -> #REF! | N36: =IF(AH29<>"",VLOOKUP($G33,'Merit Data'!A:BW,MATCH('Merit Data'!$B$3,'Merit Data'!$3:$3,0),0),TRUE) -> TRUE | X36: =IF(F36>0,HYPERLINK("http://wiki.project-saros.com/w/"&F36,"Info"),"") -> Info
A37: 0 | G37: Charisma | Z37: =CHA*5 -> #REF! | AX37: ="Further increases your Charisma score from "&CHA&" to "&CHA+1 -> #REF!
F40: =G37 -> Charisma | K40: =(CHA*(CHA-1)/2-(BaseCHA*(BaseCHA-1))/2)*5 -> #REF! | N40: =IF(AH33<>"",VLOOKUP($G37,'Merit Data'!A:BW,MATCH('Merit Data'!$B$3,'Merit Data'!$3:$3,0),0),TRUE) -> TRUE | X40: =IF(F40>0,HYPERLINK("http://wiki.project-saros.com/w/"&F40,"Info"),"") -> Info
A41: 0 | G41: Insight | Z41: =INS*5 -> #REF! | AX41: ="Further increases your Insight score from "&INS&" to "&INS+1 -> #REF!
F44: =G41 -> Insight | K44: =(INS*(INS-1)/2-(BaseINS*(BaseINS-1))/2)*5 -> #REF! | N44: =IF(AH37<>"",VLOOKUP($G41,'Merit Data'!A:BW,MATCH('Merit Data'!$B$3,'Merit Data'!$3:$3,0),0),TRUE) -> TRUE | X44: =IF(F44>0,HYPERLINK("http://wiki.project-saros.com/w/"&F44,"Info"),"") -> Info
A45: 0 | G45: Conviction | Z45: =CNV*5 -> #REF! | AX45: ="Further increases your Conviction score from "&CNV&" to "&CNV+1 -> #REF!
F48: =G45 -> Conviction | K48: =(CNV*(CNV-1)/2-(BaseCNV*(BaseCNV-1))/2)*5 -> #REF! | N48: =IF(AH41<>"",VLOOKUP($G45,'Merit Data'!A:BW,MATCH('Merit Data'!$B$3,'Merit Data'!$3:$3,0),0),TRUE) -> TRUE | X48: =IF(F48>0,HYPERLINK("http://wiki.project-saros.com/w/"&F48,"Info"),"") -> Info
A49: Combat Skills
A52: 0 | G52: Archery | Z52: =FLOOR(Archery/5+1,1)*10 -> #REF! | AX52: ="Further increases your "&G52&" skill from "&INDIRECT(SUBSTITUTE(G52," ",""))&" to "&INDIRECT(SUBSTITUTE(G52," ",""))+1 -> #REF!
F55: =G52 -> Archery | K55: =(FLOOR(INDIRECT(SUBSTITUTE(SUBSTITUTE(G52,"-","")," ",""))/5,1)*(FLOOR(INDIRECT(SUBSTITUTE(SUBSTITUTE(G52,"-","")," ",""))/5,1)+1)/2)*50+MOD(INDIRECT(SUBSTITUTE(SUBSTITUTE(G52,"-","")," ","")),5)*CEILING(INDIRECT(SUBSTITUTE(SUBSTITUTE(G52,"-","")," ",""))/5,1)*10-((FLOOR(INDIRECT("Base"&SUBSTITUTE(SUBSTITUTE(G52,"-","")," ",""))/5,1)*(FLOOR(INDIRECT("Base"&SUBSTITUTE(SUBSTITUTE(G52,"-","")," ",""))/5,1)+1)/2)*50+MOD(INDIRECT("Base"&SUBSTITUTE(SUBSTITUTE(G52,"-","")," ","")),5)*CEILING(INDIRECT("Base"&SUBSTITUTE(SUBSTITUTE(G52,"-","")," ",""))/5,1)*10) -> #REF! | N55: =IF(AH48<>"",VLOOKUP($G52,'Merit Data'!A:BW,MATCH('Merit Data'!$B$3,'Merit Data'!$3:$3,0),0),TRUE) -> TRUE | X55: =IF(F55>0,HYPERLINK("http://wiki.project-saros.com/w/"&F55,"Info"),"") -> Info
A56: 0 | G56: Axes | Z56: =FLOOR(Axes/5+1,1)*10 -> #REF! | AX56: ="Further increases your "&G56&" skill from "&Axes&" to "&Axes+1 -> #REF!
F59: =G56 -> Axes | K59: =(FLOOR(INDIRECT(SUBSTITUTE(SUBSTITUTE(G56,"-","")," ",""))/5,1)*(FLOOR(INDIRECT(SUBSTITUTE(SUBSTITUTE(G56,"-","")," ",""))/5,1)+1)/2)*50+MOD(INDIRECT(SUBSTITUTE(SUBSTITUTE(G56,"-","")," ","")),5)*CEILING(INDIRECT(SUBSTITUTE(SUBSTITUTE(G56,"-","")," ",""))/5,1)*10-((FLOOR(INDIRECT("Base"&SUBSTITUTE(SUBSTITUTE(G56,"-","")," ",""))/5,1)*(FLOOR(INDIRECT("Base"&SUBSTITUTE(SUBSTITUTE(G56,"-","")," ",""))/5,1)+1)/2)*50+MOD(INDIRECT("Base"&SUBSTITUTE(SUBSTITUTE(G56,"-","")," ","")),5)*CEILING(INDIRECT("Base"&SUBSTITUTE(SUBSTITUTE(G56,"-","")," ",""))/5,1)*10) -> #REF! | N59: =IF(AH88<>"",VLOOKUP($G56,'Merit Data'!A:BW,MATCH('Merit Data'!$B$3,'Merit Data'!$3:$3,0),0),TRUE) -> TRUE | X59: =IF(F59>0,HYPERLINK("http://wiki.project-saros.com/w/"&F59,"Info"),"") -> Info
A60: 0 | G60: Crossbows | Z60: =FLOOR(Crossbows/5+1,1)*10 -> #REF! | AX60: ="Further increases your "&G60&" skill from "&INDIRECT(SUBSTITUTE(G60," ",""))&" to "&INDIRECT(SUBSTITUTE(G60," ",""))+1 -> #REF!
F63: =G60 -> Crossbows | K63: =(FLOOR(INDIRECT(SUBSTITUTE(SUBSTITUTE(G60,"-","")," ",""))/5,1)*(FLOOR(INDIRECT(SUBSTITUTE(SUBSTITUTE(G60,"-","")," ",""))/5,1)+1)/2)*50+MOD(INDIRECT(SUBSTITUTE(SUBSTITUTE(G60,"-","")," ","")),5)*CEILING(INDIRECT(SUBSTITUTE(SUBSTITUTE(G60,"-","")," ",""))/5,1)*10-((FLOOR(INDIRECT("Base"&SUBSTITUTE(SUBSTITUTE(G60,"-","")," ",""))/5,1)*(FLOOR(INDIRECT("Base"&SUBSTITUTE(SUBSTITUTE(G60,"-","")," ",""))/5,1)+1)/2)*50+MOD(INDIRECT("Base"&SUBSTITUTE(SUBSTITUTE(G60,"-","")," ","")),5)*CEILING(INDIRECT("Base"&SUBSTITUTE(SUBSTITUTE(G60,"-","")," ",""))/5,1)*10) -> #REF! | N63: =IF(AH52<>"",VLOOKUP($G60,'Merit Data'!A:BW,MATCH('Merit Data'!$B$3,'Merit Data'!$3:$3,0),0),TRUE) -> TRUE | X63: =IF(F63>0,HYPERLINK("http://wiki.project-saros.com/w/"&F63,"Info"),"") -> Info
A64: 0 | G64: Daggers | Z64: =FLOOR(Daggers/5+1,1)*10 -> #REF! | AX64: ="Further increases your "&G64&" skill from "&INDIRECT(SUBSTITUTE(G64," ",""))&" to "&INDIRECT(SUBSTITUTE(G64," ",""))+1 -> #REF!
F67: =G64 -> Daggers | K67: =(FLOOR(INDIRECT(SUBSTITUTE(SUBSTITUTE(G64,"-","")," ",""))/5,1)*(FLOOR(INDIRECT(SUBSTITUTE(SUBSTITUTE(G64,"-","")," ",""))/5,1)+1)/2)*50+MOD(INDIRECT(SUBSTITUTE(SUBSTITUTE(G64,"-","")," ","")),5)*CEILING(INDIRECT(SUBSTITUTE(SUBSTITUTE(G64,"-","")," ",""))/5,1)*10-((FLOOR(INDIRECT("Base"&SUBSTITUTE(SUBSTITUTE(G64,"-","")," ",""))/5,1)*(FLOOR(INDIRECT("Base"&SUBSTITUTE(SUBSTITUTE(G64,"-","")," ",""))/5,1)+1)/2)*50+MOD(INDIRECT("Base"&SUBSTITUTE(SUBSTITUTE(G64,"-","")," ","")),5)*CEILING(INDIRECT("Base"&SUBSTITUTE(SUBSTITUTE(G64,"-","")," ",""))/5,1)*10) -> #REF! | N67: =IF(AH60<>"",VLOOKUP($G64,'Merit Data'!A:BW,MATCH('Merit Data'!$B$3,'Merit Data'!$3:$3,0),0),TRUE) -> TRUE | X67: =IF(F67>0,HYPERLINK("http://wiki.project-saros.com/w/"&F67,"Info"),"") -> Info
A68: 0 | G68: Hand-to-Hand Combat | Z68: =FLOOR(HandtoHandCombat/5+1,1)*10 -> #REF! | AX68: ="Further increases your "&G68&" skill from "&HandtoHandCombat&" to "&HandtoHandCombat+1 -> #REF!
F71: =G68 -> Hand-to-Hand Combat | K71: =(FLOOR(INDIRECT(SUBSTITUTE(SUBSTITUTE(G68,"-","")," ",""))/5,1)*(FLOOR(INDIRECT(SUBSTITUTE(SUBSTITUTE(G68,"-","")," ",""))/5,1)+1)/2)*50+MOD(INDIRECT(SUBSTITUTE(SUBSTITUTE(G68,"-","")," ","")),5)*CEILING(INDIRECT(SUBSTITUTE(SUBSTITUTE(G68,"-","")," ",""))/5,1)*10-((FLOOR(INDIRECT("Base"&SUBSTITUTE(SUBSTITUTE(G68,"-","")," ",""))/5,1)*(FLOOR(INDIRECT("Base"&SUBSTITUTE(SUBSTITUTE(G68,"-","")," ",""))/5,1)+1)/2)*50+MOD(INDIRECT("Base"&SUBSTITUTE(SUBSTITUTE(G68,"-","")," ","")),5)*CEILING(INDIRECT("Base"&SUBSTITUTE(SUBSTITUTE(G68,"-","")," ",""))/5,1)*10) -> #REF! | N71: =IF(AH64<>"",VLOOKUP($G68,'Merit Data'!A:BW,MATCH('Merit Data'!$B$3,'Merit Data'!$3:$3,0),0),TRUE) -> TRUE | X71: =IF(F71>0,HYPERLINK("http://wiki.project-saros.com/w/"&F71,"Info"),"") -> Info
A72: 0 | G72: Heavy Armor | Z72: =FLOOR(HeavyArmor/5+1,1)*10 -> #REF! | AX72: ="Further increases your "&G72&" skill from "&INDIRECT(SUBSTITUTE(G72," ",""))&" to "&INDIRECT(SUBSTITUTE(G72," ",""))+1 -> #REF!
F75: =G72 -> Heavy Armor | K75: =(FLOOR(INDIRECT(SUBSTITUTE(SUBSTITUTE(G72,"-","")," ",""))/5,1)*(FLOOR(INDIRECT(SUBSTITUTE(SUBSTITUTE(G72,"-","")," ",""))/5,1)+1)/2)*50+MOD(INDIRECT(SUBSTITUTE(SUBSTITUTE(G72,"-","")," ","")),5)*CEILING(INDIRECT(SUBSTITUTE(SUBSTITUTE(G72,"-","")," ",""))/5,1)*10-((FLOOR(INDIRECT("Base"&SUBSTITUTE(SUBSTITUTE(G72,"-","")," ",""))/5,1)*(FLOOR(INDIRECT("Base"&SUBSTITUTE(SUBSTITUTE(G72,"-","")," ",""))/5,1)+1)/2)*50+MOD(INDIRECT("Base"&SUBSTITUTE(SUBSTITUTE(G72,"-","")," ","")),5)*CEILING(INDIRECT("Base"&SUBSTITUTE(SUBSTITUTE(G72,"-","")," ",""))/5,1)*10) -> #REF! | N75: =IF(AH68<>"",VLOOKUP($G72,'Merit Data'!A:BW,MATCH('Merit Data'!$B$3,'Merit Data'!$3:$3,0),0),TRUE) -> TRUE | X75: =IF(F75>0,HYPERLINK("http://wiki.project-saros.com/w/"&F75,"Info"),"") -> Info
A76: 0 | G76: Improvised Weaponry | Z76: =FLOOR(ImprovisedWeaponry/5+1,1)*10 -> #NAME? | AX76: ="Further increases your "&G76&" skill from "&ImprovisedWeaponry&" to "&ImprovisedWeaponry+1 -> #NAME?
F79: =G76 -> Improvised Weaponry | K79: =(FLOOR(INDIRECT(SUBSTITUTE(SUBSTITUTE(G76,"-","")," ",""))/5,1)*(FLOOR(INDIRECT(SUBSTITUTE(SUBSTITUTE(G76,"-","")," ",""))/5,1)+1)/2)*50+MOD(INDIRECT(SUBSTITUTE(SUBSTITUTE(G76,"-","")," ","")),5)*CEILING(INDIRECT(SUBSTITUTE(SUBSTITUTE(G76,"-","")," ",""))/5,1)*10-((FLOOR(INDIRECT("Base"&SUBSTITUTE(SUBSTITUTE(G76,"-","")," ",""))/5,1)*(FLOOR(INDIRECT("Base"&SUBSTITUTE(SUBSTITUTE(G76,"-","")," ",""))/5,1)+1)/2)*50+MOD(INDIRECT("Base"&SUBSTITUTE(SUBSTITUTE(G76,"-","")," ","")),5)*CEILING(INDIRECT("Base"&SUBSTITUTE(SUBSTITUTE(G76,"-","")," ",""))/5,1)*10) -> #REF! | N79: =IF(AH72<>"",VLOOKUP($G76,'Merit Data'!A:BW,MATCH('Merit Data'!$B$3,'Merit Data'!$3:$3,0),0),TRUE) -> TRUE | X79: =IF(F79>0,HYPERLINK("http://wiki.project-saros.com/w/"&F79,"Info"),"") -> Info
A80: 0 | G80: Light Armor | Z80: =FLOOR(LightArmor/5+1,1)*10 -> #REF! | AX80: ="Further increases your "&G80&" skill from "&INDIRECT(SUBSTITUTE(G80," ",""))&" to "&INDIRECT(SUBSTITUTE(G80," ",""))+1 -> #REF!
F83: =G80 -> Light Armor | K83: =(FLOOR(INDIRECT(SUBSTITUTE(SUBSTITUTE(G80,"-","")," ",""))/5,1)*(FLOOR(INDIRECT(SUBSTITUTE(SUBSTITUTE(G80,"-","")," ",""))/5,1)+1)/2)*50+MOD(INDIRECT(SUBSTITUTE(SUBSTITUTE(G80,"-","")," ","")),5)*CEILING(INDIRECT(SUBSTITUTE(SUBSTITUTE(G80,"-","")," ",""))/5,1)*10-((FLOOR(INDIRECT("Base"&SUBSTITUTE(SUBSTITUTE(G80,"-","")," ",""))/5,1)*(FLOOR(INDIRECT("Base"&SUBSTITUTE(SUBSTITUTE(G80,"-","")," ",""))/5,1)+1)/2)*50+MOD(INDIRECT("Base"&SUBSTITUTE(SUBSTITUTE(G80,"-","")," ","")),5)*CEILING(INDIRECT("Base"&SUBSTITUTE(SUBSTITUTE(G80,"-","")," ",""))/5,1)*10) -> #REF! | N83: =IF(AH76<>"",VLOOKUP($G80,'Merit Data'!A:BW,MATCH('Merit Data'!$B$3,'Merit Data'!$3:$3,0),0),TRUE) -> TRUE | X83: =IF(F83>0,HYPERLINK("http://wiki.project-saros.com/w/"&F83,"Info"),"") -> Info
...

Sheet Merit Data
A1: =SUBSTITUTE(ADDRESS(1,COLUMN(A1),4),"1","") -> A | B1: =SUBSTITUTE(ADDRESS(1,COLUMN(B1),4),"1","") -> B | C1: =SUBSTITUTE(ADDRESS(1,COLUMN(C1),4),"1","") -> C | D1: =SUBSTITUTE(ADDRESS(1,COLUMN(D1),4),"1","") -> D | E1: =SUBSTITUTE(ADDRESS(1,COLUMN(E1),4),"1","") -> E | F1: =SUBSTITUTE(ADDRESS(1,COLUMN(F1),4),"1","") -> F | G1: =SUBSTITUTE(ADDRESS(1,COLUMN(G1),4),"1","") -> G | H1: =SUBSTITUTE(ADDRESS(1,COLUMN(H1),4),"1","") -> H | ... CK1: =SUBSTITUTE(ADDRESS(1,COLUMN(CK1),4),"1","") -> CK
J2: Merit Requirements | O2: Ability Scores | X2: Combat Skills | AR2: Expertise Skills
A3: Merit Name | B3: Qualify? | C3: Taken? | D3: Rank | E3: Exp | F3: Description | G3: Slot | H3: Type | J3: Merit 1 | K3: Merit 2 | L3: Merit 3 | M3: Special | N3: Strength | O3: Agility | P3: Constitution | Q3: Intelligence | R3: Wisdom | S3: Focus | T3: Charisma | U3: Insight | V3: Conviction | X3: Archery | Y3: Crossbows | Z3: Daggers | AA3: Hand-to-Hand Combat | AB3: Heavy Armor | AC3: Improvised Weaponry | AD3: Light Armor | AE3: Magicka | AF3: Weapon Skill | AG3: Axes | AH3: Maces | AI3: Swords | AJ3: Polearms | AK3: Shields | AL3: Staves | AM3: Throwing | AN3: NULL | AO3: NULL | AP3: NULL | AR3: Acrobatics | AS3: Appraisal | AT3: Athletics | AU3: Comprehension | AV3: Expression | AW3: Perception | AX3: Security | AY3: Stealth | AZ3: Streetwise | BA3: Subterfuge | BB3: Survival | BD3: Ancient Draconic | BE3: Aqua Elven | BF3: Basic Elven | BG3: Common | BH3: Dark Elven | BI3: Davek | BJ3: Draconic | BK3: Eulian | BL3: Garonian | BM3: Geovek | BN3: Gnomish | BO3: Goblin | BP3: High Elven | BQ3: Kotaba | BR3: Lower Common | BS3: Old Elven | BT3: Sylvan | BU3: True Draconic | BV3: Volken | BW3: Wood Elven | BX3: Prerequisites
A4: Base Merit | B4: =ISERROR(MATCH(FALSE,$J5:$BW5,0)) -> TRUE | C4: =IF(AND(INDEX('General Merits'!$F:$F,MATCH(A4,'General Merits'!$F:$F,0))>0,VLOOKUP(A4,'General Merits'!$F:$Q,10,0)),TRUE,FALSE) -> #N/A | E4: =D4*100 -> 0 | F4: CHANGE ME | BX4: =IF(BZ4<>"",BZ4,"")&IF(CA4<>"",", "&CA4,"")&IF(CB4<>"",", "&CB4,"")&IF(CC4<>"",", "&CC4,"")&IF(CD4<>"",", "&CD4,"")&IF(CE4<>"",", "&CE4,"")&IF(CF4<>"",", "&CF4,"")&IF(CG4<>"",", "&CG4,"")&IF(CH4<>"",", "&CH4,"")&IF(CI4<>"",", "&CI4,"") | BZ4: =IF(NOT(ISERROR(BZ5)),IF(NOT(ISERROR(INDIRECT(SUBSTITUTE(INDEX($1:$1048576,ROW($3:$3),SUM($BZ5:BZ5)+COLUMN($I$1)-1)," ","")&"Title"))),INDIRECT(SUBSTITUTE(INDEX($1:$1048576,ROW($3:$3),SUM($BZ5:BZ5)+COLUMN($I$1)-1)," ","")&"Title")&"("&INDEX($1:$1048576,ROW(BZ4),SUM($BZ5:BZ5)+COLUMN($I$1)-1)&")",INDEX($1:$1048576,ROW(BZ4),SUM($BZ5:BZ5)+COLUMN($I$1)-1)),"") | CA4: =IF(NOT(ISERROR(CA5)),IF(NOT(ISERROR(INDIRECT(SUBSTITUTE(INDEX($1:$1048576,ROW($3:$3),SUM($BZ5:CA5)+COLUMN($I$1)-1)," ","")&"Title"))),INDIRECT(SUBSTITUTE(INDEX($1:$1048576,ROW($3:$3),SUM($BZ5:CA5)+COLUMN($I$1)-1)," ","")&"Title")&"("&INDEX($1:$1048576,ROW(CA4),SUM($BZ5:CA5)+COLUMN($I$1)-1)&")",INDEX($1:$1048576,ROW(CA4),SUM($BZ5:CA5)+COLUMN($I$1)-1)),"") | CB4: =IF(NOT(ISERROR(CB5)),IF(NOT(ISERROR(INDIRECT(SUBSTITUTE(INDEX($1:$1048576,ROW($3:$3),SUM($BZ5:CB5)+COLUMN($I$1)-1)," ","")&"Title"))),INDIRECT(SUBSTITUTE(INDEX($1:$1048576,ROW($3:$3),SUM($BZ5:CB5)+COLUMN($I$1)-1)," ","")&"Title")&"("&INDEX($1:$1048576,ROW(CB4),SUM($BZ5:CB5)+COLUMN($I$1)-1)&")",INDEX($1:$1048576,ROW(CB4),SUM($BZ5:CB5)+COLUMN($I$1)-1)),"") | CC4: =IF(NOT(ISERROR(CC5)),IF(NOT(ISERROR(INDIRECT(SUBSTITUTE(INDEX($1:$1048576,ROW($3:$3),SUM($BZ5:CC5)+COLUMN($I$1)-1)," ","")&"Title"))),INDIRECT(SUBSTITUTE(INDEX($1:$1048576,ROW($3:$3),SUM($BZ5:CC5)+COLUMN($I$1)-1)," ","")&"Title")&"("&INDEX($1:$1048576,ROW(CC4),SUM($BZ5:CC5)+COLUMN($I$1)-1)&")",INDEX($1:$1048576,ROW(CC4),SUM($BZ5:CC5)+COLUMN($I$1)-1)),"") | CD4: =IF(NOT(ISERROR(CD5)),IF(NOT(ISERROR(INDIRECT(SUBSTITUTE(INDEX($1:$1048576,ROW($3:$3),SUM($BZ5:CD5)+COLUMN($I$1)-1)," ","")&"Title"))),INDIRECT(SUBSTITUTE(INDEX($1:$1048576,ROW($3:$3),SUM($BZ5:CD5)+COLUMN($I$1)-1)," ","")&"Title")&"("&INDEX($1:$1048576,ROW(CD4),SUM($BZ5:CD5)+COLUMN($I$1)-1)&")",INDEX($1:$1048576,ROW(CD4),SUM($BZ5:CD5)+COLUMN($I$1)-1)),"") | CE4: =IF(NOT(ISERROR(CE5)),IF(NOT(ISERROR(INDIRECT(SUBSTITUTE(INDEX($1:$1048576,ROW($3:$3),SUM($BZ5:CE5)+COLUMN($I$1)-1)," ","")&"Title"))),INDIRECT(SUBSTITUTE(INDEX($1:$1048576,ROW($3:$3),SUM($BZ5:CE5)+COLUMN($I$1)-1)," ","")&"Title")&"("&INDEX($1:$1048576,ROW(CE4),SUM($BZ5:CE5)+COLUMN($I$1)-1)&")",INDEX($1:$1048576,ROW(CE4),SUM($BZ5:CE5)+COLUMN($I$1)-1)),"") | CF4: =IF(NOT(ISERROR(CF5)),IF(NOT(ISERROR(INDIRECT(SUBSTITUTE(INDEX($1:$1048576,ROW($3:$3),SUM($BZ5:CF5)+COLUMN($I$1)-1)," ","")&"Title"))),INDIRECT(SUBSTITUTE(INDEX($1:$1048576,ROW($3:$3),SUM($BZ5:CF5)+COLUMN($I$1)-1)," ","")&"Title")&"("&INDEX($1:$1048576,ROW(CF4),SUM($BZ5:CF5)+COLUMN($I$1)-1)&")",INDEX($1:$1048576,ROW(CF4),SUM($BZ5:CF5)+COLUMN($I$1)-1)),"") | CG4: =IF(NOT(ISERROR(CG5)),IF(NOT(ISERROR(INDIRECT(SUBSTITUTE(INDEX($1:$1048576,ROW($3:$3),SUM($BZ5:CG5)+COLUMN($I$1)-1)," ","")&"Title"))),INDIRECT(SUBSTITUTE(INDEX($1:$1048576,ROW($3:$3),SUM($BZ5:CG5)+COLUMN($I$1)-1)," ","")&"Title")&"("&INDEX($1:$1048576,ROW(CG4),SUM($BZ5:CG5)+COLUMN($I$1)-1)&")",INDEX($1:$1048576,ROW(CG4),SUM($BZ5:CG5)+COLUMN($I$1)-1)),"") | ... CJ4: =IF(NOT(ISERROR(CJ5)),IF(NOT(ISERROR(INDIRECT(SUBSTITUTE(INDEX($1:$1048576,ROW($3:$3),SUM($BZ5:CJ5)+COLUMN($I$1)-1)," ","")&"Title"))),INDIRECT(SUBSTITUTE(INDEX($1:$1048576,ROW($3:$3),SUM($BZ5:CJ5)+COLUMN($I$1)-1)," ","")&"Title")&"("&INDEX($1:$1048576,ROW(CJ4),SUM($BZ5:CJ5)+COLUMN($I$1)-1)&")",INDEX($1:$1048576,ROW(CJ4),SUM($BZ5:CJ5)+COLUMN($I$1)-1)),"")
J5: =IF(J4>0,IF(AND(INDEX('General Merits'!$F:$F,MATCH($J4,'General Merits'!$F:$F,0),1)>0,VLOOKUP('Merit Data'!J4,'General Merits'!$F:$Z,COLUMN('General Merits'!$N:$N),0)),TRUE,FALSE),#N/A) -> #N/A | K5: =IF(K4>0,IF(AND(INDEX('General Merits'!$A:$A,MATCH($J4,'General Merits'!$G:$G,0),1)>0,VLOOKUP('Merit Data'!K4,'General Merits'!$A:$Z,COLUMN('General Merits'!$J:$J),0)),TRUE,FALSE),#N/A) -> #N/A | L5: =IF(L4>0,IF(AND(INDEX('General Merits'!$A:$A,MATCH($J4,'General Merits'!$G:$G,0),1)>0,VLOOKUP('Merit Data'!L4,'General Merits'!$A:$Z,COLUMN('General Merits'!$J:$J),0)),TRUE,FALSE),#N/A) -> #N/A | N5: =IF(STR>=N4,TRUE) -> #REF! | O5: =IF(AGI>=O4,TRUE) -> #REF! | P5: =IF(CON>=P4,TRUE) -> #REF! | Q5: =IF(INT>=Q4,TRUE) -> #REF! | R5: =IF(WIS>=R4,TRUE) -> #REF! | S5: =IF(FOC>=S4,TRUE) -> #REF! | T5: =IF(CHA>=T4,TRUE) -> #REF! | U5: =IF(INS>=U4,TRUE) -> #REF! | V5: =IF(CNV>=V4,TRUE) -> #REF! | X5: =IF(Archery>=X4,TRUE) -> #REF! | Y5: =IF(Crossbows>=Y4,TRUE) -> #REF! | Z5: =IF(Daggers>=Z4,TRUE) -> #REF! | AA5: =IF(HandtoHandCombat>=AA4,TRUE) -> #REF! | AB5: =IF(HeavyArmor>=AB4,TRUE) -> #REF! | AC5: =IF(ImprovisedWeaponry>=AC4,TRUE) -> #NAME? | AD5: =IF(LightArmor>=AD4,TRUE) -> #REF! | AE5: =IF(Magicka>=AE4,TRUE) -> #REF! | AF5: =IF(OR(Archery>=AF4,Crossbows>=AF4,Daggers>=AF4,HandtoHandCombat>=AF4,ImprovisedWeaponry>=AF4,Axes>=AF4,Maces>=AF4,Swords>=AF4,Polearms>=AF4,Staves>=AF4,Throwing>=AF4,TwoHandedAxes>=AF4,TwoHandedMaces>=AF4,TwoHandedSwords>=AF4),TRUE) -> #REF! | AG5: =IF(Axes>=AG4,TRUE) -> #REF! | AH5: =IF(Maces>=AH4,TRUE) -> #REF! | AI5: =IF(Swords>=AI4,TRUE) -> #REF! | AJ5: =IF(Polearms>=AJ4,TRUE) -> #REF! | AK5: =IF(Shields>=AK4,TRUE) -> #REF! | AL5: =IF(Staves>=AL4,TRUE) -> #REF! | AM5: =IF(Throwing>=AM4,TRUE) -> #REF! | AN5: =IF(TwoHandedAxes>=AN4,TRUE) -> #NAME? | AO5: =IF(TwoHandedMaces>=AO4,TRUE) -> #NAME? | AP5: =IF(TwoHandedSwords>=AP4,TRUE) -> #NAME? | AR5: =IF(Acrobatics>=AR4,TRUE) -> #REF! | AS5: =IF(Appraisal>=AS4,TRUE) -> #REF! | AT5: =IF(Athletics>=AT4,TRUE) -> #REF! | AU5: =IF(Comprehension>=AU4,TRUE) -> #REF! | AV5: =IF(Expression>=AV4,TRUE) -> #REF! | AW5: =IF(Perception>=AW4,TRUE) -> #REF! | AX5: =IF(Security>=AX4,TRUE) -> #REF! | AY5: =IF(Stealth>=AY4,TRUE) -> #REF! | AZ5: =IF(Streetwise>=AZ4,TRUE) -> #REF! | BA5: =IF(Subterfuge>=BA4,TRUE) -> #REF! | BB5: =IF(Survival>=BB4,TRUE) -> #REF! | BD5: =IF(AncientDraconic>=BD4,TRUE) -> #REF! | BE5: =IF(AquaElven>=BE4,TRUE) -> #REF! | BF5: =IF(BasicElven>=BF4,TRUE) -> #REF! | BG5: =IF(Common>=BG4,TRUE) -> #REF! | BH5: =IF(DarkElven>=BH4,TRUE) -> #REF! | BI5: =IF(Davek>=BI4,TRUE) -> #REF! | BJ5: =IF(Draconic>=BJ4,TRUE) -> #REF! | BK5: =IF(Eulian>=BK4,TRUE) -> #REF! | BL5: =IF(Garonian>=BL4,TRUE) -> #REF! | BM5: =IF(Geovek>=BM4,TRUE) -> #REF! | BN5: =IF(Gnomish>=BN4,TRUE) -> #REF! | BO5: =IF(Goblin>=BO4,TRUE) -> #REF! | BP5: =IF(HighElven>=BP4,TRUE) -> #REF! | BQ5: =IF(Kotaba>=BQ4,TRUE) -> #REF! | BR5: =IF(LowerCommon>=BR4,TRUE) -> #REF! | BS5: =IF(OldElven>=BS4,TRUE) -> #REF! | BT5: =IF(Sylvan>=BT4,TRUE) -> #REF! | BU5: =IF(TrueDraconic>=BU4,TRUE) -> #REF! | BV5: =IF(Volken>=BV4,TRUE) -> #REF! | BW5: =IF(WoodElven>=BW4,TRUE) -> #REF! | BZ5: =MATCH(TRUE,INDEX((INDIRECT(CHAR(CODE($I$1)+SUM($BY5:BY5))&$CK5-1&":"&$BW$1&$CK5-1)<>0),0),0) -> #N/A | CA5: =MATCH(TRUE,INDEX((INDIRECT(CHAR(CODE($I$1)+SUM($BY5:BZ5))&$CK5-1&":"&$BW$1&$CK5-1)<>0),0),0) -> #N/A | CB5: =MATCH(TRUE,INDEX((INDIRECT(CHAR(CODE($I$1)+SUM($BY5:CA5))&$CK5-1&":"&$BW$1&$CK5-1)<>0),0),0) -> #N/A | CC5: =MATCH(TRUE,INDEX((INDIRECT(CHAR(CODE($I$1)+SUM($BY5:CB5))&$CK5-1&":"&$BW$1&$CK5-1)<>0),0),0) -> #N/A | CD5: =MATCH(TRUE,INDEX((INDIRECT(CHAR(CODE($I$1)+SUM($BY5:CC5))&$CK5-1&":"&$BW$1&$CK5-1)<>0),0),0) -> #N/A | CE5: =MATCH(TRUE,INDEX((INDIRECT(CHAR(CODE($I$1)+SUM($BY5:CD5))&$CK5-1&":"&$BW$1&$CK5-1)<>0),0),0) -> #N/A | CF5: =MATCH(TRUE,INDEX((INDIRECT(CHAR(CODE($I$1)+SUM($BY5:CE5))&$CK5-1&":"&$BW$1&$CK5-1)<>0),0),0) -> #N/A | CG5: =MATCH(TRUE,INDEX((INDIRECT(CHAR(CODE($I$1)+SUM($BY5:CF5))&$CK5-1&":"&$BW$1&$CK5-1)<>0),0),0) -> #N/A | ... CJ5: =MATCH(TRUE,INDEX((INDIRECT(CHAR(CODE($I$1)+SUM($BY5:CI5))&$CK5-1&":"&$BW$1&$CK5-1)<>0),0),0) -> #N/A | CK5: =ROW(CK5) -> 5
A6: Tough Constitution | B6: =ISERROR(MATCH(FALSE,$J7:$BW7,0)) -> FALSE | C6: =IF(AND(INDEX('General Merits'!$F:$F,MATCH(A6,'General Merits'!$F:$F,0))>0,VLOOKUP(A6,'General Merits'!$F:$Q,10,0)),TRUE,FALSE) -> FALSE | D6: 4 | E6: =D6*100 -> 400 | F6: You gain an additional 2 health for each point of your Constitution score. | J6: Improved Stamina | BX6: =IF(BZ6<>"",BZ6,"")&IF(CA6<>"",", "&CA6,"")&IF(CB6<>"",", "&CB6,"")&IF(CC6<>"",", "&CC6,"")&IF(CD6<>"",", "&CD6,"")&IF(CE6<>"",", "&CE6,"")&IF(CF6<>"",", "&CF6,"")&IF(CG6<>"",", "&CG6,"")&IF(CH6<>"",", "&CH6,"")&IF(CI6<>"",", "&CI6,"") -> Improved Stamina | BZ6: =IF(NOT(ISERROR(BZ7)),IF(COLUMN($I:$I)+SUM($BY7:BZ7)-1<COLUMN($N:$N),INDEX($1:$1048576,ROW(BZ6),SUM($BZ7:BZ7)+COLUMN($I$1)-1),INDEX($3:$3,1,COLUMN($I:$I)+SUM($BY7:BZ7)-1)&" ("&INDEX($1:$1048576,ROW(BZ6),SUM($BZ7:BZ7)+COLUMN($I$1)-1)&")"),"") -> Improved Stamina | CA6: =IF(NOT(ISERROR(CA7)),IF(COLUMN($I:$I)+SUM($BY7:CA7)-1<COLUMN($N:$N),INDEX($1:$1048576,ROW(CA6),SUM($BZ7:CA7)+COLUMN($I$1)-1),INDEX($3:$3,1,COLUMN($I:$I)+SUM($BY7:CA7)-1)&" ("&INDEX($1:$1048576,ROW(CA6),SUM($BZ7:CA7)+COLUMN($I$1)-1)&")"),"") | CB6: =IF(NOT(ISERROR(CB7)),IF(COLUMN($I:$I)+SUM($BY7:CB7)-1<COLUMN($N:$N),INDEX($1:$1048576,ROW(CB6),SUM($BZ7:CB7)+COLUMN($I$1)-1),INDEX($3:$3,1,COLUMN($I:$I)+SUM($BY7:CB7)-1)&" ("&INDEX($1:$1048576,ROW(CB6),SUM($BZ7:CB7)+COLUMN($I$1)-1)&")"),"") | CC6: =IF(NOT(ISERROR(CC7)),IF(COLUMN($I:$I)+SUM($BY7:CC7)-1<COLUMN($N:$N),INDEX($1:$1048576,ROW(CC6),SUM($BZ7:CC7)+COLUMN($I$1)-1),INDEX($3:$3,1,COLUMN($I:$I)+SUM($BY7:CC7)-1)&" ("&INDEX($1:$1048576,ROW(CC6),SUM($BZ7:CC7)+COLUMN($I$1)-1)&")"),"") | CD6: =IF(NOT(ISERROR(CD7)),IF(COLUMN($I:$I)+SUM($BY7:CD7)-1<COLUMN($N:$N),INDEX($1:$1048576,ROW(CD6),SUM($BZ7:CD7)+COLUMN($I$1)-1),INDEX($3:$3,1,COLUMN($I:$I)+SUM($BY7:CD7)-1)&" ("&INDEX($1:$1048576,ROW(CD6),SUM($BZ7:CD7)+COLUMN($I$1)-1)&")"),"") | CE6: =IF(NOT(ISERROR(CE7)),IF(COLUMN($I:$I)+SUM($BY7:CE7)-1<COLUMN($N:$N),INDEX($1:$1048576,ROW(CE6),SUM($BZ7:CE7)+COLUMN($I$1)-1),INDEX($3:$3,1,COLUMN($I:$I)+SUM($BY7:CE7)-1)&" ("&INDEX($1:$1048576,ROW(CE6),SUM($BZ7:CE7)+COLUMN($I$1)-1)&")"),"") | CF6: =IF(NOT(ISERROR(CF7)),IF(COLUMN($I:$I)+SUM($BY7:CF7)-1<COLUMN($N:$N),INDEX($1:$1048576,ROW(CF6),SUM($BZ7:CF7)+COLUMN($I$1)-1),INDEX($3:$3,1,COLUMN($I:$I)+SUM($BY7:CF7)-1)&" ("&INDEX($1:$1048576,ROW(CF6),SUM($BZ7:CF7)+COLUMN($I$1)-1)&")"),"") | CG6: =IF(NOT(ISERROR(CG7)),IF(COLUMN($I:$I)+SUM($BY7:CG7)-1<COLUMN($N:$N),INDEX($1:$1048576,ROW(CG6),SUM($BZ7:CG7)+COLUMN($I$1)-1),INDEX($3:$3,1,COLUMN($I:$I)+SUM($BY7:CG7)-1)&" ("&INDEX($1:$1048576,ROW(CG6),SUM($BZ7:CG7)+COLUMN($I$1)-1)&")"),"") | ... CJ6: =IF(NOT(ISERROR(CJ7)),IF(COLUMN($I:$I)+SUM($BY7:CJ7)-1<COLUMN($N:$N),INDEX($1:$1048576,ROW(CJ6),SUM($BZ7:CJ7)+COLUMN($I$1)-1),INDEX($3:$3,1,COLUMN($I:$I)+SUM($BY7:CJ7)-1)&" ("&INDEX($1:$1048576,ROW(CJ6),SUM($BZ7:CJ7)+COLUMN($I$1)-1)&")"),"")
J7: =IF(J6>0,IF(AND(INDEX('General Merits'!$F:$F,MATCH($J6,'General Merits'!$F:$F,0),1)>0,VLOOKUP('Merit Data'!J6,'General Merits'!$F:$Z,COLUMN('General Merits'!$N:$N),0)),TRUE,FALSE),#N/A) -> FALSE | K7: =IF(K6>0,IF(AND(INDEX('General Merits'!$F:$F,MATCH($J6,'General Merits'!$F:$F,0),1)>0,VLOOKUP('Merit Data'!K6,'General Merits'!$F:$Z,COLUMN('General Merits'!$N:$N),0)),TRUE,FALSE),#N/A) -> #N/A | L7: =IF(L6>0,IF(AND(INDEX('General Merits'!$F:$F,MATCH($J6,'General Merits'!$F:$F,0),1)>0,VLOOKUP('Merit Data'!L6,'General Merits'!$F:$Z,COLUMN('General Merits'!$N:$N),0)),TRUE,FALSE),#N/A) -> #N/A | N7: =IF(STR>=N6,TRUE) -> #REF! | O7: =IF(AGI>=O6,TRUE) -> #REF! | P7: =IF(CON>=P6,TRUE) -> #REF! | Q7: =IF(INT>=Q6,TRUE) -> #REF! | R7: =IF(WIS>=R6,TRUE) -> #REF! | S7: =IF(FOC>=S6,TRUE) -> #REF! | T7: =IF(CHA>=T6,TRUE) -> #REF! | U7: =IF(INS>=U6,TRUE) -> #REF! | V7: =IF(CNV>=V6,TRUE) -> #REF! | X7: =IF(Archery>=X6,TRUE) -> #REF! | Y7: =IF(Crossbows>=Y6,TRUE) -> #REF! | Z7: =IF(Daggers>=Z6,TRUE) -> #REF! | AA7: =IF(HandtoHandCombat>=AA6,TRUE) -> #REF! | AB7: =IF(HeavyArmor>=AB6,TRUE) -> #REF! | AC7: =IF(ImprovisedWeaponry>=AC6,TRUE) -> #NAME? | AD7: =IF(LightArmor>=AD6,TRUE) -> #REF! | AE7: =IF(Magicka>=AE6,TRUE) -> #REF! | AF7: =IF(OR(Archery>=AF6,Crossbows>=AF6,Daggers>=AF6,HandtoHandCombat>=AF6,ImprovisedWeaponry>=AF6,Axes>=AF6,Maces>=AF6,Swords>=AF6,Polearms>=AF6,Staves>=AF6,Throwing>=AF6,TwoHandedAxes>=AF6,TwoHandedMaces>=AF6,TwoHandedSwords>=AF6),TRUE) -> #REF! | AG7: =IF(Axes>=AG6,TRUE) -> #REF! | AH7: =IF(Maces>=AH6,TRUE) -> #REF! | AI7: =IF(Swords>=AI6,TRUE) -> #REF! | AJ7: =IF(Polearms>=AJ6,TRUE) -> #REF! | AK7: =IF(Shields>=AK6,TRUE) -> #REF! | AL7: =IF(Staves>=AL6,TRUE) -> #REF! | AM7: =IF(Throwing>=AM6,TRUE) -> #REF! | AN7: =IF(TwoHandedAxes>=AN6,TRUE) -> #NAME? | AO7: =IF(TwoHandedMaces>=AO6,TRUE) -> #NAME? | AP7: =IF(TwoHandedSwords>=AP6,TRUE) -> #NAME? | AR7: =IF(Acrobatics>=AR6,TRUE) -> #REF! | AS7: =IF(Appraisal>=AS6,TRUE) -> #REF! | AT7: =IF(Athletics>=AT6,TRUE) -> #REF! | AU7: =IF(Comprehension>=AU6,TRUE) -> #REF! | AV7: =IF(Expression>=AV6,TRUE) -> #REF! | AW7: =IF(Perception>=AW6,TRUE) -> #REF! | AX7: =IF(Security>=AX6,TRUE) -> #REF! | AY7: =IF(Stealth>=AY6,TRUE) -> #REF! | AZ7: =IF(Streetwise>=AZ6,TRUE) -> #REF! | BA7: =IF(Subterfuge>=BA6,TRUE) -> #REF! | BB7: =IF(Survival>=BB6,TRUE) -> #REF! | BD7: =IF(AncientDraconic>=BD6,TRUE) -> #REF! | BE7: =IF(AquaElven>=BE6,TRUE) -> #REF! | BF7: =IF(BasicElven>=BF6,TRUE) -> #REF! | BG7: =IF(Common>=BG6,TRUE) -> #REF! | BH7: =IF(DarkElven>=BH6,TRUE) -> #REF! | BI7: =IF(Davek>=BI6,TRUE) -> #REF! | BJ7: =IF(Draconic>=BJ6,TRUE) -> #REF! | BK7: =IF(Eulian>=BK6,TRUE) -> #REF! | BL7: =IF(Garonian>=BL6,TRUE) -> #REF! | BM7: =IF(Geovek>=BM6,TRUE) -> #REF! | BN7: =IF(Gnomish>=BN6,TRUE) -> #REF! | BO7: =IF(Goblin>=BO6,TRUE) -> #REF! | BP7: =IF(HighElven>=BP6,TRUE) -> #REF! | BQ7: =IF(Kotaba>=BQ6,TRUE) -> #REF! | BR7: =IF(LowerCommon>=BR6,TRUE) -> #REF! | BS7: =IF(OldElven>=BS6,TRUE) -> #REF! | BT7: =IF(Sylvan>=BT6,TRUE) -> #REF! | BU7: =IF(TrueDraconic>=BU6,TRUE) -> #REF! | BV7: =IF(Volken>=BV6,TRUE) -> #REF! | BW7: =IF(WoodElven>=BW6,TRUE) -> #REF! | BZ7: =MATCH(TRUE,INDEX((INDIRECT(INDEX($1:$1,ROW($1:$1),COLUMN($I:$I)+SUM($BY7:BY7))&$CK7-1&":"&$BW$1&$CK7-1)<>0),0),0) -> 2 | CA7: =MATCH(TRUE,INDEX((INDIRECT(INDEX($1:$1,ROW($1:$1),COLUMN($I:$I)+SUM($BY7:BZ7))&$CK7-1&":"&$BW$1&$CK7-1)<>0),0),0) -> #N/A | CB7: =MATCH(TRUE,INDEX((INDIRECT(INDEX($1:$1,ROW($1:$1),COLUMN($I:$I)+SUM($BY7:CA7))&$CK7-1&":"&$BW$1&$CK7-1)<>0),0),0) -> #N/A | CC7: =MATCH(TRUE,INDEX((INDIRECT(INDEX($1:$1,ROW($1:$1),COLUMN($I:$I)+SUM($BY7:CB7))&$CK7-1&":"&$BW$1&$CK7-1)<>0),0),0) -> #N/A | CD7: =MATCH(TRUE,INDEX((INDIRECT(INDEX($1:$1,ROW($1:$1),COLUMN($I:$I)+SUM($BY7:CC7))&$CK7-1&":"&$BW$1&$CK7-1)<>0),0),0) -> #N/A | CE7: =MATCH(TRUE,INDEX((INDIRECT(INDEX($1:$1,ROW($1:$1),COLUMN($I:$I)+SUM($BY7:CD7))&$CK7-1&":"&$BW$1&$CK7-1)<>0),0),0) -> #N/A | CF7: =MATCH(TRUE,INDEX((INDIRECT(INDEX($1:$1,ROW($1:$1),COLUMN($I:$I)+SUM($BY7:CE7))&$CK7-1&":"&$BW$1&$CK7-1)<>0),0),0) -> #N/A | CG7: =MATCH(TRUE,INDEX((INDIRECT(INDEX($1:$1,ROW($1:$1),COLUMN($I:$I)+SUM($BY7:CF7))&$CK7-1&":"&$BW$1&$CK7-1)<>0),0),0) -> #N/A | ... CJ7: =MATCH(TRUE,INDEX((INDIRECT(INDEX($1:$1,ROW($1:$1),COLUMN($I:$I)+SUM($BY7:CI7))&$CK7-1&":"&$BW$1&$CK7-1)<>0),0),0) -> #N/A | CK7: =ROW(CK7) -> 7
A8: Purified Thoughts | B8: =ISERROR(MATCH(FALSE,$J9:$BW9,0)) -> FALSE | C8: =IF(AND(INDEX('General Merits'!$F:$F,MATCH(A8,'General Merits'!$F:$F,0))>0,VLOOKUP(A8,'General Merits'!$F:$Q,10,0)),TRUE,FALSE) -> FALSE | D8: 4 | E8: =D8*100 -> 400 | F8: You gain an additional 2 energy for each point of your Focus score. | J8: Improved Energy | BX8: =IF(BZ8<>"",BZ8,"")&IF(CA8<>"",", "&CA8,"")&IF(CB8<>"",", "&CB8,"")&IF(CC8<>"",", "&CC8,"")&IF(CD8<>"",", "&CD8,"")&IF(CE8<>"",", "&CE8,"")&IF(CF8<>"",", "&CF8,"")&IF(CG8<>"",", "&CG8,"")&IF(CH8<>"",", "&CH8,"")&IF(CI8<>"",", "&CI8,"") -> Improved Energy | BZ8: =IF(NOT(ISERROR(BZ9)),IF(COLUMN($I:$I)+SUM($BY9:BZ9)-1<COLUMN($N:$N),INDEX($1:$1048576,ROW(BZ8),SUM($BZ9:BZ9)+COLUMN($I$1)-1),INDEX($3:$3,1,COLUMN($I:$I)+SUM($BY9:BZ9)-1)&" ("&INDEX($1:$1048576,ROW(BZ8),SUM($BZ9:BZ9)+COLUMN($I$1)-1)&")"),"") -> Improved Energy | CA8: =IF(NOT(ISERROR(CA9)),IF(COLUMN($I:$I)+SUM($BY9:CA9)-1<COLUMN($N:$N),INDEX($1:$1048576,ROW(CA8),SUM($BZ9:CA9)+COLUMN($I$1)-1),INDEX($3:$3,1,COLUMN($I:$I)+SUM($BY9:CA9)-1)&" ("&INDEX($1:$1048576,ROW(CA8),SUM($BZ9:CA9)+COLUMN($I$1)-1)&")"),"") | CB8: =IF(NOT(ISERROR(CB9)),IF(COLUMN($I:$I)+SUM($BY9:CB9)-1<COLUMN($N:$N),INDEX($1:$1048576,ROW(CB8),SUM($BZ9:CB9)+COLUMN($I$1)-1),INDEX($3:$3,1,COLUMN($I:$I)+SUM($BY9:CB9)-1)&" ("&INDEX($1:$1048576,ROW(CB8),SUM($BZ9:CB9)+COLUMN($I$1)-1)&")"),"") | CC8: =IF(NOT(ISERROR(CC9)),IF(COLUMN($I:$I)+SUM($BY9:CC9)-1<COLUMN($N:$N),INDEX($1:$1048576,ROW(CC8),SUM($BZ9:CC9)+COLUMN($I$1)-1),INDEX($3:$3,1,COLUMN($I:$I)+SUM($BY9:CC9)-1)&" ("&INDEX($1:$1048576,ROW(CC8),SUM($BZ9:CC9)+COLUMN($I$1)-1)&")"),"") | CD8: =IF(NOT(ISERROR(CD9)),IF(COLUMN($I:$I)+SUM($BY9:CD9)-1<COLUMN($N:$N),INDEX($1:$1048576,ROW(CD8),SUM($BZ9:CD9)+COLUMN($I$1)-1),INDEX($3:$3,1,COLUMN($I:$I)+SUM($BY9:CD9)-1)&" ("&INDEX($1:$1048576,ROW(CD8),SUM($BZ9:CD9)+COLUMN($I$1)-1)&")"),"") | CE8: =IF(NOT(ISERROR(CE9)),IF(COLUMN($I:$I)+SUM($BY9:CE9)-1<COLUMN($N:$N),INDEX($1:$1048576,ROW(CE8),SUM($BZ9:CE9)+COLUMN($I$1)-1),INDEX($3:$3,1,COLUMN($I:$I)+SUM($BY9:CE9)-1)&" ("&INDEX($1:$1048576,ROW(CE8),SUM($BZ9:CE9)+COLUMN($I$1)-1)&")"),"") | CF8: =IF(NOT(ISERROR(CF9)),IF(COLUMN($I:$I)+SUM($BY9:CF9)-1<COLUMN($N:$N),INDEX($1:$1048576,ROW(CF8),SUM($BZ9:CF9)+COLUMN($I$1)-1),INDEX($3:$3,1,COLUMN($I:$I)+SUM($BY9:CF9)-1)&" ("&INDEX($1:$1048576,ROW(CF8),SUM($BZ9:CF9)+COLUMN($I$1)-1)&")"),"") | CG8: =IF(NOT(ISERROR(CG9)),IF(COLUMN($I:$I)+SUM($BY9:CG9)-1<COLUMN($N:$N),INDEX($1:$1048576,ROW(CG8),SUM($BZ9:CG9)+COLUMN($I$1)-1),INDEX($3:$3,1,COLUMN($I:$I)+SUM($BY9:CG9)-1)&" ("&INDEX($1:$1048576,ROW(CG8),SUM($BZ9:CG9)+COLUMN($I$1)-1)&")"),"") | ... CJ8: =IF(NOT(ISERROR(CJ9)),IF(COLUMN($I:$I)+SUM($BY9:CJ9)-1<COLUMN($N:$N),INDEX($1:$1048576,ROW(CJ8),SUM($BZ9:CJ9)+COLUMN($I$1)-1),INDEX($3:$3,1,COLUMN($I:$I)+SUM($BY9:CJ9)-1)&" ("&INDEX($1:$1048576,ROW(CJ8),SUM($BZ9:CJ9)+COLUMN($I$1)-1)&")"),"")
J9: =IF(J8>0,IF(AND(INDEX('General Merits'!$F:$F,MATCH($J8,'General Merits'!$F:$F,0),1)>0,VLOOKUP('Merit Data'!J8,'General Merits'!$F:$Z,COLUMN('General Merits'!$N:$N),0)),TRUE,FALSE),#N/A) -> FALSE | K9: =IF(K8>0,IF(AND(INDEX('General Merits'!$F:$F,MATCH($J8,'General Merits'!$F:$F,0),1)>0,VLOOKUP('Merit Data'!K8,'General Merits'!$F:$Z,COLUMN('General Merits'!$N:$N),0)),TRUE,FALSE),#N/A) -> #N/A | L9: =IF(L8>0,IF(AND(INDEX('General Merits'!$F:$F,MATCH($J8,'General Merits'!$F:$F,0),1)>0,VLOOKUP('Merit Data'!L8,'General Merits'!$F:$Z,COLUMN('General Merits'!$N:$N),0)),TRUE,FALSE),#N/A) -> #N/A | N9: =IF(STR>=N8,TRUE) -> #REF! | O9: =IF(AGI>=O8,TRUE) -> #REF! | P9: =IF(CON>=P8,TRUE) -> #REF! | Q9: =IF(INT>=Q8,TRUE) -> #REF! | R9: =IF(WIS>=R8,TRUE) -> #REF! | S9: =IF(FOC>=S8,TRUE) -> #REF! | T9: =IF(CHA>=T8,TRUE) -> #REF! | U9: =IF(INS>=U8,TRUE) -> #REF! | V9: =IF(CNV>=V8,TRUE) -> #REF! | X9: =IF(Archery>=X8,TRUE) -> #REF! | Y9: =IF(Crossbows>=Y8,TRUE) -> #REF! | Z9: =IF(Daggers>=Z8,TRUE) -> #REF! | AA9: =IF(HandtoHandCombat>=AA8,TRUE) -> #REF! | AB9: =IF(HeavyArmor>=AB8,TRUE) -> #REF! | AC9: =IF(ImprovisedWeaponry>=AC8,TRUE) -> #NAME? | AD9: =IF(LightArmor>=AD8,TRUE) -> #REF! | AE9: =IF(Magicka>=AE8,TRUE) -> #REF! | AF9: =IF(OR(Archery>=AF8,Crossbows>=AF8,Daggers>=AF8,HandtoHandCombat>=AF8,ImprovisedWeaponry>=AF8,Axes>=AF8,Maces>=AF8,Swords>=AF8,Polearms>=AF8,Staves>=AF8,Throwing>=AF8,TwoHandedAxes>=AF8,TwoHandedMaces>=AF8,TwoHandedSwords>=AF8),TRUE) -> #REF! | AG9: =IF(Axes>=AG8,TRUE) -> #REF! | AH9: =IF(Maces>=AH8,TRUE) -> #REF! | AI9: =IF(Swords>=AI8,TRUE) -> #REF! | AJ9: =IF(Polearms>=AJ8,TRUE) -> #REF! | AK9: =IF(Shields>=AK8,TRUE) -> #REF! | AL9: =IF(Staves>=AL8,TRUE) -> #REF! | AM9: =IF(Throwing>=AM8,TRUE) -> #REF! | AN9: =IF(TwoHandedAxes>=AN8,TRUE) -> #NAME? | AO9: =IF(TwoHandedMaces>=AO8,TRUE) -> #NAME? | AP9: =IF(TwoHandedSwords>=AP8,TRUE) -> #NAME? | AR9: =IF(Acrobatics>=AR8,TRUE) -> #REF! | AS9: =IF(Appraisal>=AS8,TRUE) -> #REF! | AT9: =IF(Athletics>=AT8,TRUE) -> #REF! | AU9: =IF(Comprehension>=AU8,TRUE) -> #REF! | AV9: =IF(Expression>=AV8,TRUE) -> #REF! | AW9: =IF(Perception>=AW8,TRUE) -> #REF! | AX9: =IF(Security>=AX8,TRUE) -> #REF! | AY9: =IF(Stealth>=AY8,TRUE) -> #REF! | AZ9: =IF(Streetwise>=AZ8,TRUE) -> #REF! | BA9: =IF(Subterfuge>=BA8,TRUE) -> #REF! | BB9: =IF(Survival>=BB8,TRUE) -> #REF! | BD9: =IF(AncientDraconic>=BD8,TRUE) -> #REF! | BE9: =IF(AquaElven>=BE8,TRUE) -> #REF! | BF9: =IF(BasicElven>=BF8,TRUE) -> #REF! | BG9: =IF(Common>=BG8,TRUE) -> #REF! | BH9: =IF(DarkElven>=BH8,TRUE) -> #REF! | BI9: =IF(Davek>=BI8,TRUE) -> #REF! | BJ9: =IF(Draconic>=BJ8,TRUE) -> #REF! | BK9: =IF(Eulian>=BK8,TRUE) -> #REF! | BL9: =IF(Garonian>=BL8,TRUE) -> #REF! | BM9: =IF(Geovek>=BM8,TRUE) -> #REF! | BN9: =IF(Gnomish>=BN8,TRUE) -> #REF! | BO9: =IF(Goblin>=BO8,TRUE) -> #REF! | BP9: =IF(HighElven>=BP8,TRUE) -> #REF! | BQ9: =IF(Kotaba>=BQ8,TRUE) -> #REF! | BR9: =IF(LowerCommon>=BR8,TRUE) -> #REF! | BS9: =IF(OldElven>=BS8,TRUE) -> #REF! | BT9: =IF(Sylvan>=BT8,TRUE) -> #REF! | BU9: =IF(TrueDraconic>=BU8,TRUE) -> #REF! | BV9: =IF(Volken>=BV8,TRUE) -> #REF! | BW9: =IF(WoodElven>=BW8,TRUE) -> #REF! | BZ9: =MATCH(TRUE,INDEX((INDIRECT(INDEX($1:$1,ROW($1:$1),COLUMN($I:$I)+SUM($BY9:BY9))&$CK9-1&":"&$BW$1&$CK9-1)<>0),0),0) -> 2 | CA9: =MATCH(TRUE,INDEX((INDIRECT(INDEX($1:$1,ROW($1:$1),COLUMN($I:$I)+SUM($BY9:BZ9))&$CK9-1&":"&$BW$1&$CK9-1)<>0),0),0) -> #N/A | CB9: =MATCH(TRUE,INDEX((INDIRECT(INDEX($1:$1,ROW($1:$1),COLUMN($I:$I)+SUM($BY9:CA9))&$CK9-1&":"&$BW$1&$CK9-1)<>0),0),0) -> #N/A | CC9: =MATCH(TRUE,INDEX((INDIRECT(INDEX($1:$1,ROW($1:$1),COLUMN($I:$I)+SUM($BY9:CB9))&$CK9-1&":"&$BW$1&$CK9-1)<>0),0),0) -> #N/A | CD9: =MATCH(TRUE,INDEX((INDIRECT(INDEX($1:$1,ROW($1:$1),COLUMN($I:$I)+SUM($BY9:CC9))&$CK9-1&":"&$BW$1&$CK9-1)<>0),0),0) -> #N/A | CE9: =MATCH(TRUE,INDEX((INDIRECT(INDEX($1:$1,ROW($1:$1),COLUMN($I:$I)+SUM($BY9:CD9))&$CK9-1&":"&$BW$1&$CK9-1)<>0),0),0) -> #N/A | CF9: =MATCH(TRUE,INDEX((INDIRECT(INDEX($1:$1,ROW($1:$1),COLUMN($I:$I)+SUM($BY9:CE9))&$CK9-1&":"&$BW$1&$CK9-1)<>0),0),0) -> #N/A | CG9: =MATCH(TRUE,INDEX((INDIRECT(INDEX($1:$1,ROW($1:$1),COLUMN($I:$I)+SUM($BY9:CF9))&$CK9-1&":"&$BW$1&$CK9-1)<>0),0),0) -> #N/A | ... CJ9: =MATCH(TRUE,INDEX((INDIRECT(INDEX($1:$1,ROW($1:$1),COLUMN($I:$I)+SUM($BY9:CI9))&$CK9-1&":"&$BW$1&$CK9-1)<>0),0),0) -> #N/A | CK9: =ROW(CK9) -> 9
A10: Stoic Convictions | B10: =ISERROR(MATCH(FALSE,$J11:$BW11,0)) -> FALSE | C10: =IF(AND(INDEX('General Merits'!$F:$F,MATCH(A10,'General Merits'!$F:$F,0))>0,VLOOKUP(A10,'General Merits'!$F:$Q,10,0)),TRUE,FALSE) -> FALSE | D10: 4 | E10: =D10*100 -> 400 | F10: You gain an additional 1 health and energy for each point of your Conviction score. | J10: Improved Vitality | BX10: =IF(BZ10<>"",BZ10,"")&IF(CA10<>"",", "&CA10,"")&IF(CB10<>"",", "&CB10,"")&IF(CC10<>"",", "&CC10,"")&IF(CD10<>"",", "&CD10,"")&IF(CE10<>"",", "&CE10,"")&IF(CF10<>"",", "&CF10,"")&IF(CG10<>"",", "&CG10,"")&IF(CH10<>"",", "&CH10,"")&IF(CI10<>"",", "&CI10,"") -> Improved Vitality | BZ10: =IF(NOT(ISERROR(BZ11)),IF(COLUMN($I:$I)+SUM($BY11:BZ11)-1<COLUMN($N:$N),INDEX($1:$1048576,ROW(BZ10),SUM($BZ11:BZ11)+COLUMN($I$1)-1),INDEX($3:$3,1,COLUMN($I:$I)+SUM($BY11:BZ11)-1)&" ("&INDEX($1:$1048576,ROW(BZ10),SUM($BZ11:BZ11)+COLUMN($I$1)-1)&")"),"") -> Improved Vitality | CA10: =IF(NOT(ISERROR(CA11)),IF(COLUMN($I:$I)+SUM($BY11:CA11)-1<COLUMN($N:$N),INDEX($1:$1048576,ROW(CA10),SUM($BZ11:CA11)+COLUMN($I$1)-1),INDEX($3:$3,1,COLUMN($I:$I)+SUM($BY11:CA11)-1)&" ("&INDEX($1:$1048576,ROW(CA10),SUM($BZ11:CA11)+COLUMN($I$1)-1)&")"),"") | CB10: =IF(NOT(ISERROR(CB11)),IF(COLUMN($I:$I)+SUM($BY11:CB11)-1<COLUMN($N:$N),INDEX($1:$1048576,ROW(CB10),SUM($BZ11:CB11)+COLUMN($I$1)-1),INDEX($3:$3,1,COLUMN($I:$I)+SUM($BY11:CB11)-1)&" ("&INDEX($1:$1048576,ROW(CB10),SUM($BZ11:CB11)+COLUMN($I$1)-1)&")"),"") | CC10: =IF(NOT(ISERROR(CC11)),IF(COLUMN($I:$I)+SUM($BY11:CC11)-1<COLUMN($N:$N),INDEX($1:$1048576,ROW(CC10),SUM($BZ11:CC11)+COLUMN($I$1)-1),INDEX($3:$3,1,COLUMN($I:$I)+SUM($BY11:CC11)-1)&" ("&INDEX($1:$1048576,ROW(CC10),SUM($BZ11:CC11)+COLUMN($I$1)-1)&")"),"") | CD10: =IF(NOT(ISERROR(CD11)),IF(COLUMN($I:$I)+SUM($BY11:CD11)-1<COLUMN($N:$N),INDEX($1:$1048576,ROW(CD10),SUM($BZ11:CD11)+COLUMN($I$1)-1),INDEX($3:$3,1,COLUMN($I:$I)+SUM($BY11:CD11)-1)&" ("&INDEX($1:$1048576,ROW(CD10),SUM($BZ11:CD11)+COLUMN($I$1)-1)&")"),"") | CE10: =IF(NOT(ISERROR(CE11)),IF(COLUMN($I:$I)+SUM($BY11:CE11)-1<COLUMN($N:$N),INDEX($1:$1048576,ROW(CE10),SUM($BZ11:CE11)+COLUMN($I$1)-1),INDEX($3:$3,1,COLUMN($I:$I)+SUM($BY11:CE11)-1)&" ("&INDEX($1:$1048576,ROW(CE10),SUM($BZ11:CE11)+COLUMN($I$1)-1)&")"),"") | CF10: =IF(NOT(ISERROR(CF11)),IF(COLUMN($I:$I)+SUM($BY11:CF11)-1<COLUMN($N:$N),INDEX($1:$1048576,ROW(CF10),SUM($BZ11:CF11)+COLUMN($I$1)-1),INDEX($3:$3,1,COLUMN($I:$I)+SUM($BY11:CF11)-1)&" ("&INDEX($1:$1048576,ROW(CF10),SUM($BZ11:CF11)+COLUMN($I$1)-1)&")"),"") | CG10: =IF(NOT(ISERROR(CG11)),IF(COLUMN($I:$I)+SUM($BY11:CG11)-1<COLUMN($N:$N),INDEX($1:$1048576,ROW(CG10),SUM($BZ11:CG11)+COLUMN($I$1)-1),INDEX($3:$3,1,COLUMN($I:$I)+SUM($BY11:CG11)-1)&" ("&INDEX($1:$1048576,ROW(CG10),SUM($BZ11:CG11)+COLUMN($I$1)-1)&")"),"") | ... CJ10: =IF(NOT(ISERROR(CJ11)),IF(COLUMN($I:$I)+SUM($BY11:CJ11)-1<COLUMN($N:$N),INDEX($1:$1048576,ROW(CJ10),SUM($BZ11:CJ11)+COLUMN($I$1)-1),INDEX($3:$3,1,COLUMN($I:$I)+SUM($BY11:CJ11)-1)&" ("&INDEX($1:$1048576,ROW(CJ10),SUM($BZ11:CJ11)+COLUMN($I$1)-1)&")"),"")
J11: =IF(J10>0,IF(AND(INDEX('General Merits'!$F:$F,MATCH($J10,'General Merits'!$F:$F,0),1)>0,VLOOKUP('Merit Data'!J10,'General Merits'!$F:$Z,COLUMN('General Merits'!$N:$N),0)),TRUE,FALSE),#N/A) -> FALSE | K11: =IF(K10>0,IF(AND(INDEX('General Merits'!$F:$F,MATCH($J10,'General Merits'!$F:$F,0),1)>0,VLOOKUP('Merit Data'!K10,'General Merits'!$F:$Z,COLUMN('General Merits'!$N:$N),0)),TRUE,FALSE),#N/A) -> #N/A | L11: =IF(L10>0,IF(AND(INDEX('General Merits'!$F:$F,MATCH($J10,'General Merits'!$F:$F,0),1)>0,VLOOKUP('Merit Data'!L10,'General Merits'!$F:$Z,COLUMN('General Merits'!$N:$N),0)),TRUE,FALSE),#N/A) -> #N/A | N11: =IF(STR>=N10,TRUE) -> #REF! | O11: =IF(AGI>=O10,TRUE) -> #REF! | P11: =IF(CON>=P10,TRUE) -> #REF! | Q11: =IF(INT>=Q10,TRUE) -> #REF! | R11: =IF(WIS>=R10,TRUE) -> #REF! | S11: =IF(FOC>=S10,TRUE) -> #REF! | T11: =IF(CHA>=T10,TRUE) -> #REF! | U11: =IF(INS>=U10,TRUE) -> #REF! | V11: =IF(CNV>=V10,TRUE) -> #REF! | X11: =IF(Archery>=X10,TRUE) -> #REF! | Y11: =IF(Crossbows>=Y10,TRUE) -> #REF! | Z11: =IF(Daggers>=Z10,TRUE) -> #REF! | AA11: =IF(HandtoHandCombat>=AA10,TRUE) -> #REF! | AB11: =IF(HeavyArmor>=AB10,TRUE) -> #REF! | AC11: =IF(ImprovisedWeaponry>=AC10,TRUE) -> #NAME? | AD11: =IF(LightArmor>=AD10,TRUE) -> #REF! | AE11: =IF(Magicka>=AE10,TRUE) -> #REF! | AF11: =IF(OR(Archery>=AF10,Crossbows>=AF10,Daggers>=AF10,HandtoHandCombat>=AF10,ImprovisedWeaponry>=AF10,Axes>=AF10,Maces>=AF10,Swords>=AF10,Polearms>=AF10,Staves>=AF10,Throwing>=AF10,TwoHandedAxes>=AF10,TwoHandedMaces>=AF10,TwoHandedSwords>=AF10),TRUE) -> #REF! | AG11: =IF(Axes>=AG10,TRUE) -> #REF! | AH11: =IF(Maces>=AH10,TRUE) -> #REF! | AI11: =IF(Swords>=AI10,TRUE) -> #REF! | AJ11: =IF(Polearms>=AJ10,TRUE) -> #REF! | AK11: =IF(Shields>=AK10,TRUE) -> #REF! | AL11: =IF(Staves>=AL10,TRUE) -> #REF! | AM11: =IF(Throwing>=AM10,TRUE) -> #REF! | AN11: =IF(TwoHandedAxes>=AN10,TRUE) -> #NAME? | AO11: =IF(TwoHandedMaces>=AO10,TRUE) -> #NAME? | AP11: =IF(TwoHandedSwords>=AP10,TRUE) -> #NAME? | AR11: =IF(Acrobatics>=AR10,TRUE) -> #REF! | AS11: =IF(Appraisal>=AS10,TRUE) -> #REF! | AT11: =IF(Athletics>=AT10,TRUE) -> #REF! | AU11: =IF(Comprehension>=AU10,TRUE) -> #REF! | AV11: =IF(Expression>=AV10,TRUE) -> #REF! | AW11: =IF(Perception>=AW10,TRUE) -> #REF! | AX11: =IF(Security>=AX10,TRUE) -> #REF! | AY11: =IF(Stealth>=AY10,TRUE) -> #REF! | AZ11: =IF(Streetwise>=AZ10,TRUE) -> #REF! | BA11: =IF(Subterfuge>=BA10,TRUE) -> #REF! | BB11: =IF(Survival>=BB10,TRUE) -> #REF! | BD11: =IF(AncientDraconic>=BD10,TRUE) -> #REF! | BE11: =IF(AquaElven>=BE10,TRUE) -> #REF! | BF11: =IF(BasicElven>=BF10,TRUE) -> #REF! | BG11: =IF(Common>=BG10,TRUE) -> #REF! | BH11: =IF(DarkElven>=BH10,TRUE) -> #REF! | BI11: =IF(Davek>=BI10,TRUE) -> #REF! | BJ11: =IF(Draconic>=BJ10,TRUE) -> #REF! | BK11: =IF(Eulian>=BK10,TRUE) -> #REF! | BL11: =IF(Garonian>=BL10,TRUE) -> #REF! | BM11: =IF(Geovek>=BM10,TRUE) -> #REF! | BN11: =IF(Gnomish>=BN10,TRUE) -> #REF! | BO11: =IF(Goblin>=BO10,TRUE) -> #REF! | BP11: =IF(HighElven>=BP10,TRUE) -> #REF! | BQ11: =IF(Kotaba>=BQ10,TRUE) -> #REF! | BR11: =IF(LowerCommon>=BR10,TRUE) -> #REF! | BS11: =IF(OldElven>=BS10,TRUE) -> #REF! | BT11: =IF(Sylvan>=BT10,TRUE) -> #REF! | BU11: =IF(TrueDraconic>=BU10,TRUE) -> #REF! | BV11: =IF(Volken>=BV10,TRUE) -> #REF! | BW11: =IF(WoodElven>=BW10,TRUE) -> #REF! | BZ11: =MATCH(TRUE,INDEX((INDIRECT(INDEX($1:$1,ROW($1:$1),COLUMN($I:$I)+SUM($BY11:BY11))&$CK11-1&":"&$BW$1&$CK11-1)<>0),0),0) -> 2 | CA11: =MATCH(TRUE,INDEX((INDIRECT(INDEX($1:$1,ROW($1:$1),COLUMN($I:$I)+SUM($BY11:BZ11))&$CK11-1&":"&$BW$1&$CK11-1)<>0),0),0) -> #N/A | CB11: =MATCH(TRUE,INDEX((INDIRECT(INDEX($1:$1,ROW($1:$1),COLUMN($I:$I)+SUM($BY11:CA11))&$CK11-1&":"&$BW$1&$CK11-1)<>0),0),0) -> #N/A | CC11: =MATCH(TRUE,INDEX((INDIRECT(INDEX($1:$1,ROW($1:$1),COLUMN($I:$I)+SUM($BY11:CB11))&$CK11-1&":"&$BW$1&$CK11-1)<>0),0),0) -> #N/A | CD11: =MATCH(TRUE,INDEX((INDIRECT(INDEX($1:$1,ROW($1:$1),COLUMN($I:$I)+SUM($BY11:CC11))&$CK11-1&":"&$BW$1&$CK11-1)<>0),0),0) -> #N/A | CE11: =MATCH(TRUE,INDEX((INDIRECT(INDEX($1:$1,ROW($1:$1),COLUMN($I:$I)+SUM($BY11:CD11))&$CK11-1&":"&$BW$1&$CK11-1)<>0),0),0) -> #N/A | CF11: =MATCH(TRUE,INDEX((INDIRECT(INDEX($1:$1,ROW($1:$1),COLUMN($I:$I)+SUM($BY11:CE11))&$CK11-1&":"&$BW$1&$CK11-1)<>0),0),0) -> #N/A | CG11: =MATCH(TRUE,INDEX((INDIRECT(INDEX($1:$1,ROW($1:$1),COLUMN($I:$I)+SUM($BY11:CF11))&$CK11-1&":"&$BW$1&$CK11-1)<>0),0),0) -> #N/A | ... CJ11: =MATCH(TRUE,INDEX((INDIRECT(INDEX($1:$1,ROW($1:$1),COLUMN($I:$I)+SUM($BY11:CI11))&$CK11-1&":"&$BW$1&$CK11-1)<>0),0),0) -> #N/A | CK11: =ROW(CK11) -> 11
A12: Deep Sleeper | B12: =ISERROR(MATCH(FALSE,$J13:$BW13,0)) -> TRUE | C12: =IF(AND(INDEX('General Merits'!$F:$F,MATCH(A12,'General Merits'!$F:$F,0))>0,VLOOKUP(A12,'General Merits'!$F:$Q,10,0)),TRUE,FALSE) -> FALSE | D12: 1 | E12: =D12*100 -> 100 | F12: You fall asleep quickly, allowing better sleep. You are considered restfully sleeping and receive full energy regeneration even in uncomfortable or interrupted sleep. | S12: 18 | BX12: =IF(BZ12<>"",BZ12,"")&IF(CA12<>"",", "&CA12,"")&IF(CB12<>"",", "&CB12,"")&IF(CC12<>"",", "&CC12,"")&IF(CD12<>"",", "&CD12,"")&IF(CE12<>"",", "&CE12,"")&IF(CF12<>"",", "&CF12,"")&IF(CG12<>"",", "&CG12,"")&IF(CH12<>"",", "&CH12,"")&IF(CI12<>"",", "&CI12,"") -> Focus (18) | BZ12: =IF(NOT(ISERROR(BZ13)),IF(COLUMN($I:$I)+SUM($BY13:BZ13)-1<COLUMN($N:$N),INDEX($1:$1048576,ROW(BZ12),SUM($BZ13:BZ13)+COLUMN($I$1)-1),INDEX($3:$3,1,COLUMN($I:$I)+SUM($BY13:BZ13)-1)&" ("&INDEX($1:$1048576,ROW(BZ12),SUM($BZ13:BZ13)+COLUMN($I$1)-1)&")"),"") -> Focus (18) | CA12: =IF(NOT(ISERROR(CA13)),IF(COLUMN($I:$I)+SUM($BY13:CA13)-1<COLUMN($N:$N),INDEX($1:$1048576,ROW(CA12),SUM($BZ13:CA13)+COLUMN($I$1)-1),INDEX($3:$3,1,COLUMN($I:$I)+SUM($BY13:CA13)-1)&" ("&INDEX($1:$1048576,ROW(CA12),SUM($BZ13:CA13)+COLUMN($I$1)-1)&")"),"") | CB12: =IF(NOT(ISERROR(CB13)),IF(COLUMN($I:$I)+SUM($BY13:CB13)-1<COLUMN($N:$N),INDEX($1:$1048576,ROW(CB12),SUM($BZ13:CB13)+COLUMN($I$1)-1),INDEX($3:$3,1,COLUMN($I:$I)+SUM($BY13:CB13)-1)&" ("&INDEX($1:$1048576,ROW(CB12),SUM($BZ13:CB13)+COLUMN($I$1)-1)&")"),"") | CC12: =IF(NOT(ISERROR(CC13)),IF(COLUMN($I:$I)+SUM($BY13:CC13)-1<COLUMN($N:$N),INDEX($1:$1048576,ROW(CC12),SUM($BZ13:CC13)+COLUMN($I$1)-1),INDEX($3:$3,1,COLUMN($I:$I)+SUM($BY13:CC13)-1)&" ("&INDEX($1:$1048576,ROW(CC12),SUM($BZ13:CC13)+COLUMN($I$1)-1)&")"),"") | CD12: =IF(NOT(ISERROR(CD13)),IF(COLUMN($I:$I)+SUM($BY13:CD13)-1<COLUMN($N:$N),INDEX($1:$1048576,ROW(CD12),SUM($BZ13:CD13)+COLUMN($I$1)-1),INDEX($3:$3,1,COLUMN($I:$I)+SUM($BY13:CD13)-1)&" ("&INDEX($1:$1048576,ROW(CD12),SUM($BZ13:CD13)+COLUMN($I$1)-1)&")"),"") | CE12: =IF(NOT(ISERROR(CE13)),IF(COLUMN($I:$I)+SUM($BY13:CE13)-1<COLUMN($N:$N),INDEX($1:$1048576,ROW(CE12),SUM($BZ13:CE13)+COLUMN($I$1)-1),INDEX($3:$3,1,COLUMN($I:$I)+SUM($BY13:CE13)-1)&" ("&INDEX($1:$1048576,ROW(CE12),SUM($BZ13:CE13)+COLUMN($I$1)-1)&")"),"") | CF12: =IF(NOT(ISERROR(CF13)),IF(COLUMN($I:$I)+SUM($BY13:CF13)-1<COLUMN($N:$N),INDEX($1:$1048576,ROW(CF12),SUM($BZ13:CF13)+COLUMN($I$1)-1),INDEX($3:$3,1,COLUMN($I:$I)+SUM($BY13:CF13)-1)&" ("&INDEX($1:$1048576,ROW(CF12),SUM($BZ13:CF13)+COLUMN($I$1)-1)&")"),"") | CG12: =IF(NOT(ISERROR(CG13)),IF(COLUMN($I:$I)+SUM($BY13:CG13)-1<COLUMN($N:$N),INDEX($1:$1048576,ROW(CG12),SUM($BZ13:CG13)+COLUMN($I$1)-1),INDEX($3:$3,1,COLUMN($I:$I)+SUM($BY13:CG13)-1)&" ("&INDEX($1:$1048576,ROW(CG12),SUM($BZ13:CG13)+COLUMN($I$1)-1)&")"),"") | ... CJ12: =IF(NOT(ISERROR(CJ13)),IF(COLUMN($I:$I)+SUM($BY13:CJ13)-1<COLUMN($N:$N),INDEX($1:$1048576,ROW(CJ12),SUM($BZ13:CJ13)+COLUMN($I$1)-1),INDEX($3:$3,1,COLUMN($I:$I)+SUM($BY13:CJ13)-1)&" ("&INDEX($1:$1048576,ROW(CJ12),SUM($BZ13:CJ13)+COLUMN($I$1)-1)&")"),"")
